Workbook
Name EscenarioActivo: Escenarios!$B$4

Sheet Dashboard
A1: DASHBOARD — Super Meseros | H1: ⚡ ESCENARIO | J1: Año 1 | K1: Año 2 | L1: Año 3 | M1: Año 4 | N1: Año 5
A2: Métricas financieras y operativas · Datos dinámicos vinculados al modelo · Escenario activo: | F2: =CHOOSE(Escenarios!B4,"PESIMISTA","BASE","OPTIMISTA") | H2: =CHOOSE(Escenarios!B4,"PESIMISTA","BASE","OPTIMISTA") | I2: Ingresos | J2: =B5 | K2: =C5 | L2: =D5 | M2: =E5 | N2: =F5
H3: =HYPERLINK("#Escenarios!B4","✏️ Cambiar escenario →") | I3: EBITDA | J3: =B10 | K3: =C10 | L3: =D10 | M3: =E10 | N3: =F10
A4: P&L ANUAL | B4: Año 1 | C4: Año 2 | D4: Año 3 | E4: Año 4 | F4: Año 5 | G4: Total 60m | I4: Utilidad Neta | J4: =B11 | K4: =C11 | L4: =D11 | M4: =E11 | N4: =F11
A5: Ingresos | B5: =SUM('Estados Financieros'!B8:M8) | C5: =SUM('Estados Financieros'!N8:Y8) | D5: =SUM('Estados Financieros'!Z8:AK8) | E5: =SUM('Estados Financieros'!AL8:AW8) | F5: =SUM('Estados Financieros'!AX8:BI8) | G5: ='Estados Financieros'!BJ8
A6: Costos Directos | B6: =SUM('Estados Financieros'!B11:M11) | C6: =SUM('Estados Financieros'!N11:Y11) | D6: =SUM('Estados Financieros'!Z11:AK11) | E6: =SUM('Estados Financieros'!AL11:AW11) | F6: =SUM('Estados Financieros'!AX11:BI11) | G6: ='Estados Financieros'!BJ11 | J6: Año 1 | K6: Año 2 | L6: Año 3 | M6: Año 4 | N6: Año 5
A7: Utilidad Bruta | B7: =B5-B6 | C7: =C5-C6 | D7: =D5-D6 | E7: =E5-E6 | F7: =F5-F6 | G7: =G5-G6 | I7: Restaurantes activos | J7: =B15 | K7: =C15 | L7: =D15 | M7: =E15 | N7: =F15
A8: CAC y GTM | B8: =SUM('Estados Financieros'!B16:M16) | C8: =SUM('Estados Financieros'!N16:Y16) | D8: =SUM('Estados Financieros'!Z16:AK16) | E8: =SUM('Estados Financieros'!AL16:AW16) | F8: =SUM('Estados Financieros'!AX16:BI16) | G8: ='Estados Financieros'!BJ16
A9: OPEX | B9: =SUM('Estados Financieros'!B21:M21) | C9: =SUM('Estados Financieros'!N21:Y21) | D9: =SUM('Estados Financieros'!Z21:AK21) | E9: =SUM('Estados Financieros'!AL21:AW21) | F9: =SUM('Estados Financieros'!AX21:BI21) | G9: ='Estados Financieros'!BJ21 | J9: Año 1 | K9: Año 2 | L9: Año 3 | M9: Año 4 | N9: Año 5
A10: EBITDA | B10: =SUM('Estados Financieros'!B22:M22) | C10: =SUM('Estados Financieros'!N22:Y22) | D10: =SUM('Estados Financieros'!Z22:AK22) | E10: =SUM('Estados Financieros'!AL22:AW22) | F10: =SUM('Estados Financieros'!AX22:BI22) | G10: ='Estados Financieros'!BJ22 | I10: Margen Bruto | J10: =B17 | K10: =C17 | L10: =D17 | M10: =E17 | N10: =F17
A11: Utilidad Neta | B11: =SUM('Estados Financieros'!B25:M25) | C11: =SUM('Estados Financieros'!N25:Y25) | D11: =SUM('Estados Financieros'!Z25:AK25) | E11: =SUM('Estados Financieros'!AL25:AW25) | F11: =SUM('Estados Financieros'!AX25:BI25) | G11: ='Estados Financieros'!BJ25 | I11: Margen EBITDA | J11: =B18 | K11: =C18 | L11: =D18 | M11: =E18 | N11: =F18
A12: Caja Final | B12: ='Estados Financieros'!M31 | C12: ='Estados Financieros'!Y31 | D12: ='Estados Financieros'!AK31 | E12: ='Estados Financieros'!AW31 | F12: ='Estados Financieros'!BI31 | G12: ='Estados Financieros'!BJ31 | I12: Margen Neto | J12: =B19 | K12: =C19 | L12: =D19 | M12: =E19 | N12: =F19
A14: KPIs OPERATIVOS | B14: Año 1 | C14: Año 2 | D14: Año 3 | E14: Año 4 | F14: Año 5 | J14: Año 1 | K14: Año 2 | L14: Año 3 | M14: Año 4 | N14: Año 5
A15: Rest. activos (fin año) | B15: ='Estados Financieros'!M35 | C15: ='Estados Financieros'!Y35 | D15: ='Estados Financieros'!AK35 | E15: ='Estados Financieros'!AW35 | F15: ='Estados Financieros'!BI35 | I15: Costos Directos | J15: =B6 | K15: =C6 | L15: =D6 | M15: =E6 | N15: =F6
A16: Meseros activos (fin año) | B16: ='Estados Financieros'!M36 | C16: ='Estados Financieros'!Y36 | D16: ='Estados Financieros'!AK36 | E16: ='Estados Financieros'!AW36 | F16: ='Estados Financieros'!BI36 | I16: CAC y GTM | J16: =B8 | K16: =C8 | L16: =D8 | M16: =E8 | N16: =F8
A17: Margen Bruto | B17: =IF(B5=0,0,B7/B5) | C17: =IF(C5=0,0,C7/C5) | D17: =IF(D5=0,0,D7/D5) | E17: =IF(E5=0,0,E7/E5) | F17: =IF(F5=0,0,F7/F5) | I17: OPEX | J17: =B9 | K17: =C9 | L17: =D9 | M17: =E9 | N17: =F9
A18: Margen EBITDA | B18: =IF(B5=0,0,B10/B5) | C18: =IF(C5=0,0,C10/C5) | D18: =IF(D5=0,0,D10/D5) | E18: =IF(E5=0,0,E10/E5) | F18: =IF(F5=0,0,F10/F5) | I18: EBITDA | J18: =B10 | K18: =C10 | L18: =D10 | M18: =E10 | N18: =F10
A19: Margen Neto | B19: =IF(B5=0,0,B11/B5) | C19: =IF(C5=0,0,C11/C5) | D19: =IF(D5=0,0,D11/D5) | E19: =IF(E5=0,0,E11/E5) | F19: =IF(F5=0,0,F11/F5)
J20: Año 1 | K20: Año 2 | L20: Año 3 | M20: Año 4 | N20: Año 5
A21: VALORACIÓN & DEAL STRUCTURE | D21: ALIANZAS ACTIVAS | E21: Estado | F21: Rest/mes | I21: Restaurantes activos | J21: =B15 | K21: =C15 | L21: =D15 | M21: =E15 | N21: =F15
A22: Valoración Pre-Money (ponderada) | B22: =Valoración!C52 | D22: Coca-Cola | E22: =IF(Palancas!B13=1,"✅ ON","❌ OFF") | F22: =IF(Palancas!B13=1,Palancas!B16,0) | I22: Caja Final | J22: =B12 | K22: =C12 | L22: =D12 | M22: =E12 | N22: =F12
A23: Monto a levantar | B23: =Valoración!C56 | D23: ACODRES | E23: =IF(Palancas!F13=1,"✅ ON","❌ OFF") | F23: =IF(Palancas!F13=1,Palancas!F16,0)
A24: Valoración Post-Money | B24: =Valoración!C57 | D24: Bavaria | E24: =IF(Palancas!B21=1,"✅ ON","❌ OFF") | F24: =IF(Palancas!B21=1,Palancas!B24,0)
A25: Dilución del fundador | B25: =Valoración!C58 | D25: FEMSA | E25: =IF(Palancas!F21=1,"✅ ON","❌ OFF") | F25: =IF(Palancas!F21=1,Palancas!F24,0)
A26: ARR Pipeline | B26: =Valoración!C33 | D26: CC Florida | E26: =IF(Palancas!B29=1,"✅ ON","❌ OFF") | F26: =IF(Palancas!B29=1,Palancas!B32,0)
A27: ARR Modelo Año 1 | B27: =Valoración!C36
A28: Restaurantes mes 60 | B28: =Valoración!C40 | D28: Total alianzas/mes | E28: =COUNTIF(E22:E26,"✅ ON") | F28: =SUM(F22:F26)

Sheet Unit Economics
A1: UNIT ECONOMICS — Simulador por Restaurante | D1: ⚡ ESCENARIO
C2: =CHOOSE(Escenarios!B4,"PESIMISTA","BASE","OPTIMISTA") | D2: =HYPERLINK("#Escenarios!B4","✏️ Cambiar →")
A3: 📊 INPUT DEL INVERSIONISTA
A5: Número de restaurantes | B5: 1 | C5: ← Cambie este número
A7: PARÁMETROS BASE (1 Restaurante) | C7: Valor | D7: Fuente
A8: Meseros promedio por restaurante | C8: ='Supuestos Generales'!B19 | D8: Supuestos B19
A9: % de meseros activos | C9: ='Supuestos Generales'!B20 | D9: Supuestos B20
A10: Meseros activos por restaurante | C10: =C8*C9 | D10: Calculado
A11: Marcas promedio por restaurante | C11: ='Supuestos Generales'!B28 | D11: Supuestos B28
A13: INGRESOS ONE-OFF (por restaurante nuevo) | C13: USD | D13: Fuente
A14: SetUp Fee | C14: ='Supuestos Generales'!B24 | D14: Supuestos B24
A15: Entry Fee (por marca) | C15: ='Supuestos Generales'!B25*C11 | D15: B25 × marcas
A16: Total Ingresos One-Off | C16: =C14+C15 | D16: Suma
A18: INGRESOS RECURRENTES / MES (por restaurante) | C18: USD/mes | D18: Fuente
A19: SaaS Fee Restaurante (por mesero activo) | C19: ='Supuestos Generales'!B26*C10 | D19: B26 × activos
A20: SaaS Fee Marcas (por mesero activo × marcas) | C20: ='Supuestos Generales'!B27*C10*C11 | D20: B27 × activos × marcas
A21: Fee Upgrade de Plan | C21: ='Supuestos Generales'!B59*'Supuestos Generales'!B60 | D21: B59 × B60 (% upgrade × fee)
A22: Super Monedas — Restaurantes (bruto) | C22: ='Supuestos Generales'!B31*C10 | D22: B31 × activos
A23: Super Monedas — Marcas (bruto) | C23: ='Supuestos Generales'!B32*C10*C11 | D23: B32 × activos × marcas
A24: Total Super Monedas (bruto) | C24: =C22+C23
A25: Ingreso neto Super Monedas (breakage + margen) | C25: =C24*('Supuestos Generales'!B34+'Supuestos Generales'!B33*'Supuestos Generales'!B35) | D25: breakage + margen redención
A27: Total Ingresos Recurrentes / Mes | C27: =C19+C20+C21+C24 | D27: Suma SaaS + SM neto
A28: Ingreso Anualizado (1 restaurante) | C28: =C27*12 | D28: Recurrente × 12
A30: ESCALAMIENTO — Total por Número de Restaurantes | C30: USD | D30: Fórmula
A31: Restaurantes | C31: =B5 | D31: ← Input B5
A32: Total Ingresos One-Off | C32: =C16*C31 | D32: One-off × restaurantes
A33: Total Ingresos Recurrentes / Mes | C33: =C27*C31 | D33: Recurrente × restaurantes
A34: Total Ingreso Anualizado | C34: =C28*C31 | D34: Anualizado × restaurantes
A36: Ingreso recurrente mensual por restaurante (referencia) | C36: =C27 | D36: Constante

Sheet Resumen Escenarios
A1: MASTER WAITERS (Super Meseros) | G1: ⚡ ESCENARIO
A2: Resumen de Escenarios Financieros · Modelo v4.0 · Datos dinámicos vinculados al modelo · Copiar y pegar en pitch deck | G2: =CHOOSE(Escenarios!B4,"PESIMISTA","BASE","OPTIMISTA")
G3: =HYPERLINK("#Escenarios!B4","✏️ Cambiar escenario →")
A5: 1. CONTEXTO DEL MODELO
A6: Horizonte: 60 meses (5 años). Caja inicial: $500,000 USD. Ramp-up lineal de alianzas (12–24 meses según escenario). Segmentación por tamaño de restaurante (Pricing v2.5).
A8: Fuentes de Ingresos: SetUp Fee ($500/rest), Entry Fee ($300/rest-marca), SaaS Fee (ARPU ponderado por segmento), Fee Upgrade ($50 × %upgrade), Super Monedas (programa gamificado).
A10: Alianzas Estratégicas Contempladas
A11: Alianza | B11: Pipeline | C11: Mercado | D11: Descripción
A12: Coca-Cola | B12: 5,000 rest. | C12: Colombia | D12: Exclusividad confirmada
A13: ACODRES | B13: 12,000 rest. | C13: Colombia | D13: Gremio de restaurantes
A14: Bavaria | B14: 4,500 rest. | C14: Colombia | D14: Interés en implementar SM
A15: FEMSA Ventures | B15: 50,000 rest. | C15: México | D15: Interés en invertir
A16: Coca-Cola Florida | B16: 5,000 rest. | C16: USA | D16: Piloto → expansión
A18: 2. DEFINICIÓN DE ESCENARIOS
A19: Parámetro | B19: 🔴 Pesimista | C19: 🟡 Base | D19: 🟢 Optimista
A20: Alianzas activas | B20: =DF140 | C20: =DF167 | D20: =DF194
A21: Rest/mes por alianza | B21: =CHOOSE(1,Escenarios!$D$49) | C21: =CHOOSE(1,Escenarios!$E$49) | D21: =CHOOSE(1,Escenarios!$F$49)
A22: Meses de ramp-up | B22: =Escenarios!D51 | C22: =Escenarios!E51 | D22: =Escenarios!F51
A23: Churn mensual | B23: =Escenarios!D17 | C23: =Escenarios!E17 | D23: =Escenarios!F17
A24: Meseros ponderados/rest | B24: =BP140 | C24: =BP167 | D24: =BP194
A25: ARPU neto ponderado | B25: =BS140 | C25: =BS167 | D25: =BS194
A26: % meseros activos | B26: =Escenarios!D18 | C26: =Escenarios!E18 | D26: =Escenarios!F18
A27: Marcas por restaurante | B27: =Escenarios!D21 | C27: =Escenarios!E21 | D27: =Escenarios!F21
A28: % Restaurantes Pequeños | B28: =Escenarios!D28 | C28: =Escenarios!E28 | D28: =Escenarios!F28
A29: % Restaurantes Medianos | B29: =Escenarios!D29 | C29: =Escenarios!E29 | D29: =Escenarios!F29
A30: % Restaurantes Grandes | B30: =Escenarios!D30 | C30: =Escenarios!E30 | D30: =Escenarios!F30
A31: % Upgrade de Plan | B31: =Escenarios!D31 | C31: =Escenarios!E31 | D31: =Escenarios!F31
A32: OPEX factor | B32: =Escenarios!D34 | C32: =Escenarios!E34 | D32: =Escenarios!F34
A34: 3. RESULTADOS FINANCIEROS — COMPARATIVO A 60 MESES
A35: Métrica | B35: 🔴 Pesimista | C35: 🟡 Base | D35: 🟢 Optimista | E35: Ratio Opt/Pes
A36: Restaurantes activos (mes 60) | B36: =DG140 | C36: =DG167 | D36: =DG194 | E36: =IF(OR(B36<=0,D36<=0),"n.m.",D36/B36)
A37: Ingresos totales (60m) | B37: =DH140 | C37: =DH167 | D37: =DH194 | E37: =IF(OR(B37<=0,D37<=0),"n.m.",D37/B37)
A38: Costos directos (60m) | B38: =DI140 | C38: =DI167 | D38: =DI194 | E38: =IF(OR(B38<=0,D38<=0),"n.m.",D38/B38)
A39: Utilidad bruta (60m) | B39: =DJ140 | C39: =DJ167 | D39: =DJ194 | E39: =IF(OR(B39<=0,D39<=0),"n.m.",D39/B39)
A40: Margen bruto | B40: =IF(DH140=0,0,DJ140/DH140) | C40: =IF(DH167=0,0,DJ167/DH167) | D40: =IF(DH194=0,0,DJ194/DH194) | E40: =IF(OR(B40<=0,D40<=0),"n.m.",D40/B40)
A41: EBITDA acumulado (60m) | B41: =DK140 | C41: =DK167 | D41: =DK194 | E41: =IF(OR(B41<=0,D41<=0),"n.m.",D41/B41)
A42: Margen EBITDA | B42: =IF(DH140=0,0,DK140/DH140) | C42: =IF(DH167=0,0,DK167/DH167) | D42: =IF(DH194=0,0,DK194/DH194) | E42: =IF(OR(B42<=0,D42<=0),"n.m.",D42/B42)
A43: Utilidad neta (60m) | B43: =DL140 | C43: =DL167 | D43: =DL194 | E43: =IF(OR(B43<=0,D43<=0),"n.m.",D43/B43)
A44: Margen neto | B44: =IF(DH140=0,0,DL140/DH140) | C44: =IF(DH167=0,0,DL167/DH167) | D44: =IF(DH194=0,0,DL194/DH194) | E44: =IF(OR(B44<=0,D44<=0),"n.m.",D44/B44)
A45: Caja final (mes 60) | B45: =DM140 | C45: =DM167 | D45: =DM194 | E45: =IF(OR(B45<=0,D45<=0),"n.m.",D45/B45)
...

Sheet Documentación
A1: DOCUMENTACIÓN DEL MODELO FINANCIERO
A2: Super Meseros — Plataforma SaaS B2B2C para Meseros de Restaurante
A3: Versión 4.0 | Marzo 2026 | Horizonte: 60 meses | Incluye: Ramp-up lineal, Palancas dinámicas, CAC alianzas, Valoración dinámica, Unit Economics, Dashboard, Referidos editables (B68), Comparativo 3 escenarios, Margen SM por escenario, SM params por escenario, Directos ajustados Pes/Base, Segmentación de restaurantes (Pricing v2.5), Fee Upgrade de Plan
A5: TABLA DE CONTENIDOS
A6: 1. Resumen Ejecutivo | B6: Fila 23
A7: 2. Arquitectura del Modelo | B7: Fila 41
A8: 3. Supuestos Generales (Parámetros) | B8: Fila 64
A9: 4. Motor de Onboarding y Crecimiento | B9: Fila 148
A10: 5. Modelo de Ingresos | B10: Fila 221
A11: 6. Estructura de Costos | B11: Fila 253
A12: 7. CAC y Go-to-Market | B12: Fila 297
A13: 8. Estados Financieros (P&L + Cash Flow) | B13: Fila 353
A14: 9. Análisis de Escenarios | B14: Fila 392
A15: 10. Tablas de Sensibilidad | B15: Fila 447
A16: 11. Sistema de Palancas de Crecimiento | B16: Fila 475
A17: 12. Valoración Interactiva | B17: Fila 508 (+12b. Unit Economics: Fila 528)
... A21: 16–19. Supuestos, Guía de Uso, Glosario, Política de Costos | B21: Filas 673+ (16: F673, 17: F701, 18: F726, 19: F746)
A23: 1. RESUMEN EJECUTIVO
A25: Super Meseros es una plataforma SaaS B2B2C que conecta restaurantes, marcas y meseros mediante tecnología, gamificación y Super Monedas. El modelo proyecta 60 meses de operación con crecimiento orgánico en 5 fases + 5 palancas de alianzas estratégicas vinculadas al escenario activo (Pesimista: 2 alianzas CC+ACODRES, Base: 2 alianzas CC+ACODRES, Optimista: 5 alianzas). Las alianzas incorporan un ramp-up lineal gradual (Pes: 24m, Base: 18m, Opt: 12m). El margen de Super Meseros sobre redención de SM es diferenciado por escenario (Pes 10%, Base 15%, Opt 15%). Los 5 parámetros de SM (compra rest/marcas, % redención, breakage, % efectivo) son variables por escenario (v3.8). Directos orgánicos ajustados: Pes 2/4/8/14/20, Base 3/5/9/15/22. Los referidos son editables (Sup.Gen B68=2). Incluye CAC diferenciado para alianzas ($60/rest), hoja de Valoración dinámica con ponderación editable (C23=30% Pipeline), hoja Unit Economics para inversionista, y Dashboard 100% dinámico con 5 gráficos.
A27: MÉTRICAS CLAVE DEL CASO BASE (Escenario Base — 2 alianzas activas: CC + ACODRES a 25 rest/mes, ramp-up 18m, directos 3/5/9/15/22, B68=2, Margen SM 15%, 90 rest/EM, 65 rest/CS)
A29: Métrica | B29: Valor
A30: Total Ingresos (60 meses) | B30: $161,002,698 USD
A31: Total Costos Directos (60 meses) | B31: $96,741,485 USD
A32: Utilidad Bruta (60 meses) | B32: $64,261,213 USD
A33: Margen Bruto promedio | B33: 0.399
A34: EBITDA acumulado (60 meses) | B34: $49,146,081 USD
A35: Margen EBITDA promedio | B35: 0.305
A36: Caja Final (Mes 60) | B36: $32,378,658 USD
A37: Caja Inicial (Funding) | B37: $500,000 USD
A38: ROI sobre inversión inicial | B38: 6,476% ($32.4M / $500K)
A39: Restaurantes activos (Mes 60) | B39: 5383
A41: 2. ARQUITECTURA DEL MODELO
A43: El modelo se compone de 9 hojas interconectadas. Todos los parámetros fluyen desde Supuestos Generales hacia las hojas operativas y financieras.
A45: Hoja | B45: Función
A46: 1. Supuestos Generales | B46: Parámetros centrales del modelo (113 filas)
A47: 2. Onboarding | B47: Crecimiento: restaurantes orgánicos + alianzas + referidos, meseros, marcas
A48: 3. Ingresos | B48: One-Off (SetUp + Entry) + Recurrentes (SaaS + Super Monedas)
A49: 4. Costos Directos | B49: Variables + Engagement + CS (reclasificado de OPEX)
A50: 5. CAC y GTM | B50: Costos de adquisición directos + alianzas ($60/rest), comisiones, publicidad, LTV/CAC
A51: 6. OPEX | B51: Costos fijos con step-ups condicionales a EBITDA + Gerente + Licencia
...

Sheet Escenarios
A1: ESCENARIOS Y SENSIBILIDAD | H1: 📖 GUÍA PARA EL INVERSIONISTA
A3: SELECTOR DE ESCENARIO | H3: ¿QUÉ ES ESTA HOJA?
A4: Escenario activo → | B4: 1 | C4: ← Cambiar: 1 = Pesimista, 2 = Base, 3 = Optimista | H4: Esta hoja le permite explorar tres versiones del futuro de Super Meseros: una pesimista, una base (la más probable) y una optimista. Cada escenario usa supuestos diferentes sobre cuántos restaurantes se suman, cuántos se van, cuánto pagan y cuánto cuesta operar.
A5: Escenario seleccionado: | B5: =CHOOSE(B4,"PESIMISTA","BASE (actual)","OPTIMISTA")
A7: PARÁMETROS POR ESCENARIO | D7: Pesimista | E7: Base | F7: Optimista | G7: =HYPERLINK("#Escenarios!H1","📖 Ver Guía para el Inversionista →")
A8: ONBOARDING | H8: ¿CÓMO SE USA?
A9: Directos/mes — Fase 1 (Piloto) | B9: rest/mes | C9: =HYPERLINK("#'Supuestos Generales'!B12","→ Sup.Gen B12") | D9: 2 | E9: 3 | F9: 3 | H9: Paso 1 → Cambie el número en la celda B4 (amarilla, arriba a la izquierda):
A10: Directos/mes — Fase 2 (Tracción) | B10: rest/mes | C10: =HYPERLINK("#'Supuestos Generales'!B13","→ Sup.Gen B13") | D10: 4 | E10: 5 | F10: 6 | H10: 1 = Pesimista | 2 = Base (actual) | 3 = Optimista
A11: Directos/mes — Fase 3 (Crecimiento) | B11: rest/mes | C11: =HYPERLINK("#'Supuestos Generales'!B14","→ Sup.Gen B14") | D11: 8 | E11: 9 | F11: 10 | H11: Al cambiar ese número, TODO el modelo financiero se recalcula automáticamente: ingresos, costos, márgenes, caja y los resultados de la sección "Resultados del Escenario Activo" (filas 28-41).
A12: Directos/mes — Fase 4 (Consolidación) | B12: rest/mes | C12: =HYPERLINK("#'Supuestos Generales'!B15","→ Sup.Gen B15") | D12: 14 | E12: 15 | F12: 18
A13: Directos/mes — Fase 5 (Madurez orgánica) | B13: rest/mes | C13: =HYPERLINK("#'Supuestos Generales'!B16","→ Sup.Gen B16") | D13: 20 | E13: 22 | F13: 27 | H13: Paso 2 → Revise la sección "Parámetros por Escenario" (filas 7-26):
H14: Aquí verá los supuestos que alimentan cada escenario en tres columnas: D (Pesimista en rosado), E (Base en verde) y F (Optimista en azul). Estos valores SÍ son editables: si quiere probar qué pasa con un churn de 4% en vez de 3%, simplemente cambie el valor en la celda correspondiente y el modelo se ajustará.
A15: UNIT ECONOMICS
A16: Meseros promedio por restaurante | B16: # | C16: =HYPERLINK("#'Supuestos Generales'!B41","→ Ahora por segmentos (Sup.Gen B41:B52)") | D16: 5 | E16: 8 | F16: 10
A17: Churn mensual restaurantes | B17: % | C17: =HYPERLINK("#'Supuestos Generales'!B18","→ Sup.Gen B18 (fórmula)") | D17: 0.05 | E17: 0.03 | F17: 0.02 | H17: Paso 3 → Consulte los resultados (filas 28-41):
A18: % meseros activos | B18: % | C18: =HYPERLINK("#'Supuestos Generales'!B20","→ Sup.Gen B20 (fórmula)") | D18: 0.75 | E18: 0.85 | F18: 0.95 | H18: Esta sección muestra el resumen financiero a 60 meses del escenario activo: ingresos totales, EBITDA, utilidad neta, caja final, restaurantes activos y el mes en que se alcanza EBITDA positivo. Todos estos valores se actualizan solos al cambiar B4 o cualquier parámetro.
A19: ARPU restaurante (USD/mesero) | B19: USD | C19: =HYPERLINK("#'Supuestos Generales'!B41","→ Ahora por segmentos (Sup.Gen B41:B56)") | D19: 10 | E19: 15 | F19: 20
A20: ARPU marcas (USD/mesero) | B20: USD | C20: =HYPERLINK("#'Supuestos Generales'!B27","→ Sup.Gen B27 (fórmula)") | D20: 7 | E20: 10 | F20: 15
A21: Marcas promedio por restaurante | B21: # | C21: =HYPERLINK("#'Supuestos Generales'!B28","→ Sup.Gen B28 (fórmula)") | D21: 1 | E21: 2 | F21: 3 | H21: ¿QUÉ SIGNIFICAN LOS PARÁMETROS?
A22: SM compra por restaurante (USD/mesero/mes) | B22: USD | C22: → Sup.Gen B31 (fórmula) | D22: 25 | E22: 35 | F22: 50
A23: SM compra por marca (USD/mesero/mes) | B23: USD | C23: → Sup.Gen B32 (fórmula) | D23: 10 | E23: 20 | F23: 25
A24: % SM redimidas por meseros | B24: % | C24: → Sup.Gen B33 (fórmula) | D24: 0.9 | E24: 0.85 | F24: 0.8
A25: % breakage (SM que vencen) | B25: % | C25: → Sup.Gen B34 (fórmula) | D25: 0.08 | E25: 0.1 | F25: 0.12
A26: % redenciones en efectivo | B26: % | C26: → Sup.Gen B36 (fórmula) | D26: 0.8 | E26: 0.7 | F26: 0.6
A27: SEGMENTACIÓN | C27: =HYPERLINK("#'Supuestos Generales'!B41","→ Sup.Gen B41:B43 (fórmula)")
A28: % Restaurantes Pequeños | B28: % | C28: =HYPERLINK("#'Supuestos Generales'!B41","→ Sup.Gen B41 (fórmula)") | D28: 0.7 | E28: 0.5 | F28: 0.35
A29: % Restaurantes Medianos | B29: % | C29: =HYPERLINK("#'Supuestos Generales'!B42","→ Sup.Gen B42 (fórmula)") | D29: 0.25 | E29: 0.35 | F29: 0.35
A30: % Restaurantes Grandes | B30: % | C30: =HYPERLINK("#'Supuestos Generales'!B43","→ Sup.Gen B43 (fórmula)") | D30: 0.05 | E30: 0.15 | F30: 0.3
A31: % Restaurantes que hacen upgrade | B31: % | C31: =HYPERLINK("#'Supuestos Generales'!B59","→ Sup.Gen B59 (fórmula)") | D31: 0.05 | E31: 0.1 | F31: 0.2
H32: ONBOARDING (filas 9-13): Cuántos restaurantes nuevos se captan por mes en cada fase de crecimiento. Fase 1 es el piloto inicial; Fase 5 es escala completa.
A33: COSTOS Y OPEX
A34: Factor escala OPEX fijo | B34: x | C34: =HYPERLINK("#'Supuestos Generales'!B105","→ Sup.Gen B105 (fórmula)") | D34: 0.46 | E34: 1 | F34: 2 | H34: UNIT ECONOMICS (filas 16-20): Las métricas unitarias del negocio. Churn = % de restaurantes que se van cada mes. ARPU = ingreso promedio mensual por mesero activo. Marcas = cuántas marcas patrocinan por restaurante.
A35: Crecimiento semestral OPEX | B35: % | C35: =HYPERLINK("#'Supuestos Generales'!B102","→ Sup.Gen B102 (fórmula)") | D35: 0.15 | E35: 0.1 | F35: 0.08
A36: Soporte por restaurante | B36: USD | C36: =HYPERLINK("#'Supuestos Generales'!B49","→ Sup.Gen B49 (fórmula)") | D36: 30 | E36: 25 | F36: 20 | H36: COSTOS Y OPEX (filas 23-26): OPEX base = gasto fijo mensual (equipo, tecnología, legal). Crecimiento OPEX = cuánto sube cada semestre. Soporte = costo de atender cada restaurante. Caja inicial = capital disponible al arrancar.
A37: Restaurantes por EM | B37: # | C37: =HYPERLINK("#'Supuestos Generales'!B59","→ Sup.Gen B59 (fórmula)") | D37: 75 | E37: 90 | F37: 100
A38: Restaurantes por Agente CS | B38: # | C38: =HYPERLINK("#'Supuestos Generales'!B50","→ Sup.Gen B50 (fórmula)") | D38: 50 | E38: 65 | F38: 80
A39: Margen Super Meseros sobre redención | B39: % | C39: → Sup.Gen B35 (fórmula) | D39: 0.1 | E39: 0.15 | F39: 0.15
A40: Caja inicial (funding) | B40: USD | C40: =HYPERLINK("#'Supuestos Generales'!B8","→ Sup.Gen B8 (editable)") | D40: 500000 | E40: 500000 | F40: 500000
A43: PALANCAS DE ALIANZAS
A44: Toggle Coca-Cola | B44: 0/1 | C44: → Palancas B10 | D44: 1 | E44: 1 | F44: 1
...

Sheet Palancas
A1: PALANCAS DE CRECIMIENTO — Alianzas Estratégicas | F1: ⚡ ESCENARIO
A2: Toggles y velocidades controlados por escenario (Escenarios!B4). Para override manual: editar valores en Escenarios filas 32-38. | F2: =CHOOSE(Escenarios!B4,"PESIMISTA","BASE","OPTIMISTA")
F3: =HYPERLINK("#Escenarios!B4","✏️ Cambiar escenario →")
A4: MODO DE CONTROL | B4: AUTOMÁTICO | C4: ← Toggles y velocidades controlados por escenario. Para override: editar valores en Escenarios filas 32-38.
A6: PARÁMETROS GLOBALES
A7: % Solapamiento entre alianzas | B7: 0.35 | C7: ← Editable
A8: Pipeline neto total (ajust. solapamiento) | B8: =ROUND((B14+F14+B22)*(1-B7)+F22+B30, 0) | C8: restaurantes
A9: CAC por restaurante vía alianzas | B9: 60 | C9: USD / rest
A10: Meses ramp-up alianzas | B10: =CHOOSE(Escenarios!$B$4,Escenarios!$D$51,Escenarios!$E$51,Escenarios!$F$51) | C10: meses
A12: COCA-COLA | B12: Valor | E12: ACODRES | F12: Valor
A13: Toggle ON/OFF | B13: =CHOOSE(Escenarios!$B$4,Escenarios!$D$44,Escenarios!$E$44,Escenarios!$F$44) | C13: 1=ON, 0=OFF | E13: Toggle ON/OFF | F13: =CHOOSE(Escenarios!$B$4,Escenarios!$D$45,Escenarios!$E$45,Escenarios!$F$45) | G13: 1=ON, 0=OFF
A14: Pipeline total | B14: 5000 | C14: rest | E14: Pipeline total | F14: 12000 | G14: rest
A15: Mes de activación | B15: 6 | C15: mes | E15: Mes de activación | F15: 6 | G15: mes
A16: Restaurantes/mes | B16: =CHOOSE(Escenarios!$B$4,Escenarios!$D$49,Escenarios!$E$49,Escenarios!$F$49) | C16: rest/mes | E16: Restaurantes/mes | F16: =CHOOSE(Escenarios!$B$4,Escenarios!$D$49,Escenarios!$E$49,Escenarios!$F$49) | G16: rest/mes
A17: Pipeline neto (ajust. solap.) | B17: =ROUND(B14*(1-$B$7), 0) | C17: rest | E17: Pipeline neto (ajust. solap.) | F17: =ROUND(F14*(1-$B$7), 0) | G17: rest
A18: Meses para agotar pipeline | B18: =IF(B16=0,"-",CEILING(B17/B16,1)) | C18: meses | E18: Meses para agotar pipeline | F18: =IF(F16=0,"-",CEILING(F17/F16,1)) | G18: meses
A20: BAVARIA | B20: Valor | E20: FEMSA VENTURES (México) | F20: Valor
A21: Toggle ON/OFF | B21: =CHOOSE(Escenarios!$B$4,Escenarios!$D$46,Escenarios!$E$46,Escenarios!$F$46) | C21: 1=ON, 0=OFF | E21: Toggle ON/OFF | F21: =CHOOSE(Escenarios!$B$4,Escenarios!$D$47,Escenarios!$E$47,Escenarios!$F$47) | G21: 1=ON, 0=OFF
A22: Pipeline total | B22: 4500 | C22: rest | E22: Pipeline total | F22: 50000 | G22: rest
A23: Mes de activación | B23: 12 | C23: mes | E23: Mes de activación | F23: 24 | G23: mes
A24: Restaurantes/mes | B24: =CHOOSE(Escenarios!$B$4,Escenarios!$D$49,Escenarios!$E$49,Escenarios!$F$49) | C24: rest/mes | E24: Restaurantes/mes | F24: =CHOOSE(Escenarios!$B$4,Escenarios!$D$49,Escenarios!$E$49,Escenarios!$F$49) | G24: rest/mes
A25: Pipeline neto (ajust. solap.) | B25: =ROUND(B22*(1-$B$7), 0) | C25: rest | E25: Pipeline neto (sin solapamiento) | F25: =F22 | G25: rest
A26: Meses para agotar pipeline | B26: =IF(B24=0,"-",CEILING(B25/B24,1)) | C26: meses | E26: Meses para agotar pipeline | F26: =IF(F24=0,"-",CEILING(F25/F24,1)) | G26: meses
A28: COCA-COLA FLORIDA (USA) | B28: Valor
A29: Toggle ON/OFF | B29: =CHOOSE(Escenarios!$B$4,Escenarios!$D$48,Escenarios!$E$48,Escenarios!$F$48) | C29: 1=ON, 0=OFF
A30: Pipeline total | B30: 5000 | C30: rest
A31: Mes de activación | B31: 36 | C31: mes
A32: Restaurantes/mes | B32: =CHOOSE(Escenarios!$B$4,Escenarios!$D$50,Escenarios!$E$50,Escenarios!$F$50) | C32: rest/mes
A33: Pipeline neto (sin solapamiento) | B33: =B30 | C33: rest
A34: Mes fin (auto por pipeline) | B34: =IF(B32=0,60,MIN(60,B31+CEILING(B30/B32,1)-1)) | C34: mes
A35: Meses para agotar pipeline | B35: =IF(B32=0,"-",CEILING(B33/B32,1)) | C35: meses

Sheet Supuestos Generales
A1: SUPUESTOS GENERALES
A2: Super Meseros - SaaS B2B2C - Plataforma Gamificada de Motivación y Reconocimiento para Meseros
A4: PARÁMETROS GENERALES | B4: Valor | C4: Notas
A5: Mes de inicio | B5: 1 | C5: Mes 1 = inicio de operaciones
A6: Horizonte del modelo (meses) | B6: 60 | C6: 5 años de proyección mensual
A7: Moneda | B7: USD | C7: Dólares americanos
A8: Caja inicial (funding) | B8: 500000 | C8: Capital semilla / pre-seed
A10: RESTAURANTES Y ONBOARDING | B10: Valor | C10: Notas
A11: Rampa de onboarding por fase | B11: Mes inicio | C11: Mes fin | D11: Directos/mes
A12: Fase 1 — Piloto | B12: =CHOOSE(Escenarios!$B$4,Escenarios!$D$9,Escenarios!$E$9,Escenarios!$F$9) | C12: 3 | D12: =CHOOSE(Escenarios!$B$4,Escenarios!$D$9,Escenarios!$E$9,Escenarios!$F$9) | E12: =HYPERLINK("#Escenarios!D9","→ Modificar en Escenarios!D9:F9")
A13: Fase 2 — Tracción | B13: =CHOOSE(Escenarios!$B$4,Escenarios!$D$10,Escenarios!$E$10,Escenarios!$F$10) | C13: 6 | D13: =CHOOSE(Escenarios!$B$4,Escenarios!$D$10,Escenarios!$E$10,Escenarios!$F$10) | E13: =HYPERLINK("#Escenarios!D10","→ Modificar en Escenarios!D10:F10")
A14: Fase 3 — Crecimiento | B14: =CHOOSE(Escenarios!$B$4,Escenarios!$D$11,Escenarios!$E$11,Escenarios!$F$11) | C14: 12 | D14: =CHOOSE(Escenarios!$B$4,Escenarios!$D$11,Escenarios!$E$11,Escenarios!$F$11) | E14: =HYPERLINK("#Escenarios!D11","→ Modificar en Escenarios!D11:F11")
A15: Fase 4 — Consolidación | B15: =CHOOSE(Escenarios!$B$4,Escenarios!$D$12,Escenarios!$E$12,Escenarios!$F$12) | C15: 24 | D15: =CHOOSE(Escenarios!$B$4,Escenarios!$D$12,Escenarios!$E$12,Escenarios!$F$12) | E15: =HYPERLINK("#Escenarios!D12","→ Modificar en Escenarios!D12:F12")
A16: Fase 5 — Madurez orgánica | B16: =CHOOSE(Escenarios!$B$4,Escenarios!$D$13,Escenarios!$E$13,Escenarios!$F$13) | C16: 60 | D16: =CHOOSE(Escenarios!$B$4,Escenarios!$D$13,Escenarios!$E$13,Escenarios!$F$13) | E16: =HYPERLINK("#Escenarios!D13","→ Modificar en Escenarios!D13:F13")
A18: Churn mensual de restaurantes (%) | B18: =CHOOSE(Escenarios!$B$4,Escenarios!$D$17,Escenarios!$E$17,Escenarios!$F$17) | C18: % de restaurantes que salen por mes | D18: =HYPERLINK("#Escenarios!D16","→ Modificar en Escenarios!D16:F16")
A19: Meseros promedio por restaurante | B19: =B57 | C19: Promedio de meseros por restaurante | D19: → Modificar en Escenarios!D16:F16
A20: % de meseros activos | B20: =CHOOSE(Escenarios!$B$4,Escenarios!$D$18,Escenarios!$E$18,Escenarios!$F$18) | C20: Meseros que usan activamente la plataforma | D20: =HYPERLINK("#Escenarios!D17","→ Modificar en Escenarios!D17:F17")
A21: Churn mensual de meseros (%) | B21: 0.05 | C21: Rotación natural de meseros
A23: FEES E INGRESOS | B23: Valor | C23: Notas
A24: SetUp Fee por restaurante (one-time) | B24: 500 | C24: Cobro único al incorporar restaurante
A25: Entry Fee por restaurante-marca (one-time) | B25: 300 | C25: Cobro a marca por entrar en un restaurante
A26: ARPU mensual por mesero (restaurante) | B26: =B56 | C26: ← Ahora calculado por mix de segmentos (ver fila 56) | D26: =HYPERLINK("#'Supuestos Generales'!B41","→ Modificar mix en B41:B43, fees en B46:B48")
A27: ARPU mensual por mesero (marcas) | B27: =CHOOSE(Escenarios!$B$4,Escenarios!$D$20,Escenarios!$E$20,Escenarios!$F$20) | C27: Fee recurrente cobrado a marcas | D27: =HYPERLINK("#Escenarios!D19","→ Modificar en Escenarios!D19:F19")
A28: Marcas promedio por restaurante | B28: =CHOOSE(Escenarios!$B$4,Escenarios!$D$21,Escenarios!$E$21,Escenarios!$F$21) | C28: Número de marcas activas por restaurante | D28: =HYPERLINK("#Escenarios!D20","→ Modificar en Escenarios!D20:F20")
A29: Crecimiento mensual de marcas/restaurante (%) | B29: 0.01 | C29: Aumento gradual de marcas por restaurante
A30: — SUPER MONEDAS —
A31: Compra de Super Monedas por restaurante (USD/mes/mesero) | B31: =CHOOSE(Escenarios!$B$4,Escenarios!$D$22,Escenarios!$E$22,Escenarios!$F$22) | C31: Monto que restaurantes compran en monedas por mesero
A32: Compra de Super Monedas por marca (USD/mes/mesero) | B32: =CHOOSE(Escenarios!$B$4,Escenarios!$D$23,Escenarios!$E$23,Escenarios!$F$23) | C32: Monto que marcas compran en monedas por mesero
A33: % de Super Monedas redimidas por meseros | B33: =CHOOSE(Escenarios!$B$4,Escenarios!$D$24,Escenarios!$E$24,Escenarios!$F$24) | C33: Porcentaje que los meseros efectivamente canjean
A34: % de Super Monedas que vencen (breakage) | B34: =CHOOSE(Escenarios!$B$4,Escenarios!$D$25,Escenarios!$E$25,Escenarios!$F$25) | C34: Monedas no redimidas = ingreso para Super Meseros
A35: Margen de Super Meseros sobre redención (%) | B35: =CHOOSE(Escenarios!$B$4,Escenarios!$D$39,Escenarios!$E$39,Escenarios!$F$39) | C35: Ingreso neto = 20% de lo que meseros redimen
A36: % de redenciones Super Monedas en efectivo | B36: =CHOOSE(Escenarios!$B$4,Escenarios!$D$26,Escenarios!$E$26,Escenarios!$F$26) | C36: % de meseros que canjean monedas por dinero en efectivo
A37: Tasa pasarela de pago (%) | B37: 0.035 | C37: Comisión procesador de pagos sobre transacciones
A38: Tasa de impuestos sobre utilidades (%) | B38: 0.35 | C38: Impuesto de renta corporativo (Colombia)
A39: SEGMENTACIÓN DE RESTAURANTES | B39: Valor | C39: Notas
A40: — Mix de Segmentos (% del total de restaurantes) —
A41: % Restaurantes Pequeños (Plan Light) | B41: =CHOOSE(Escenarios!$B$4,Escenarios!$D$28,Escenarios!$E$28,Escenarios!$F$28) | C41: Ventas $10K-$80K/mes, 5 meseros típicos | D41: =HYPERLINK("#Escenarios!D28","→ Modificar en Escenarios!D28:F28")
A42: % Restaurantes Medianos (Plan Standard) | B42: =CHOOSE(Escenarios!$B$4,Escenarios!$D$29,Escenarios!$E$29,Escenarios!$F$29) | C42: Ventas $80K-$200K/mes, 10 meseros típicos | D42: =HYPERLINK("#Escenarios!D29","→ Modificar en Escenarios!D29:F29")
A43: % Restaurantes Grandes (Plan Premium) | B43: =CHOOSE(Escenarios!$B$4,Escenarios!$D$30,Escenarios!$E$30,Escenarios!$F$30) | C43: Ventas $200K-$500K/mes, 25 meseros típicos | D43: =HYPERLINK("#Escenarios!D30","→ Modificar en Escenarios!D30:F30")
A44: Validación mix | B44: =B41+B42+B43 | C44: =IF(B44=1,"✓ Suma 100%","⚠️ NO suma 100%")
...

Sheet Onboarding
A1: ONBOARDING — Proyección de Restaurantes, Meseros y Marcas
A3: Concepto | B3: 1 | C3: 2 | D3: 3 | E3: 4 | F3: 5 | G3: 6 | H3: 7 | I3: 8 | J3: 9 | K3: 10 | L3: 11 | M3: 12 | N3: 13 | O3: 14 | P3: 15 | Q3: 16 | R3: 17 | S3: 18 | T3: 19 | U3: 20 | V3: 21 | W3: 22 | X3: 23 | Y3: 24 | Z3: 25 | AA3: 26 | AB3: 27 | AC3: 28 | AD3: 29 | AE3: 30 | AF3: 31 | AG3: 32 | AH3: 33 | AI3: 34 | AJ3: 35 | AK3: 36 | AL3: 37 | AM3: 38 | AN3: 39 | AO3: 40 | AP3: 41 | AQ3: 42 | AR3: 43 | AS3: 44 | AT3: 45 | AU3: 46 | AV3: 47 | AW3: 48 | AX3: 49 | AY3: 50 | AZ3: 51 | BA3: 52 | BB3: 53 | BC3: 54 | BD3: 55 | BE3: 56 | BF3: 57 | BG3: 58 | BH3: 59 | BI3: 60
A5: RESTAURANTES
A6: Restaurantes nuevos directos | B6: =IF(B3<='Supuestos Generales'!$C$12,'Supuestos Generales'!$D$12,IF(B3<='Supuestos Generales'!$C$13,'Supuestos Generales'!$D$13,IF(B3<='Supuestos Generales'!$C$14,'Supuestos Generales'!$D$14,IF(B3<='Supuestos Generales'!$C$15,'Supuestos Generales'!$D$15,'Supuestos Generales'!$D$16)))) | C6: =IF(C3<='Supuestos Generales'!$C$12,'Supuestos Generales'!$D$12,IF(C3<='Supuestos Generales'!$C$13,'Supuestos Generales'!$D$13,IF(C3<='Supuestos Generales'!$C$14,'Supuestos Generales'!$D$14,IF(C3<='Supuestos Generales'!$C$15,'Supuestos Generales'!$D$15,'Supuestos Generales'!$D$16)))) | D6: =IF(D3<='Supuestos Generales'!$C$12,'Supuestos Generales'!$D$12,IF(D3<='Supuestos Generales'!$C$13,'Supuestos Generales'!$D$13,IF(D3<='Supuestos Generales'!$C$14,'Supuestos Generales'!$D$14,IF(D3<='Supuestos Generales'!$C$15,'Supuestos Generales'!$D$15,'Supuestos Generales'!$D$16)))) | E6: =IF(E3<='Supuestos Generales'!$C$12,'Supuestos Generales'!$D$12,IF(E3<='Supuestos Generales'!$C$13,'Supuestos Generales'!$D$13,IF(E3<='Supuestos Generales'!$C$14,'Supuestos Generales'!$D$14,IF(E3<='Supuestos Generales'!$C$15,'Supuestos Generales'!$D$15,'Supuestos Generales'!$D$16)))) | F6: =IF(F3<='Supuestos Generales'!$C$12,'Supuestos Generales'!$D$12,IF(F3<='Supuestos Generales'!$C$13,'Supuestos Generales'!$D$13,IF(F3<='Supuestos Generales'!$C$14,'Supuestos Generales'!$D$14,IF(F3<='Supuestos Generales'!$C$15,'Supuestos Generales'!$D$15,'Supuestos Generales'!$D$16)))) | G6: =IF(G3<='Supuestos Generales'!$C$12,'Supuestos Generales'!$D$12,IF(G3<='Supuestos Generales'!$C$13,'Supuestos Generales'!$D$13,IF(G3<='Supuestos Generales'!$C$14,'Supuestos Generales'!$D$14,IF(G3<='Supuestos Generales'!$C$15,'Supuestos Generales'!$D$15,'Supuestos Generales'!$D$16)))) | H6: =IF(H3<='Supuestos Generales'!$C$12,'Supuestos Generales'!$D$12,IF(H3<='Supuestos Generales'!$C$13,'Supuestos Generales'!$D$13,IF(H3<='Supuestos Generales'!$C$14,'Supuestos Generales'!$D$14,IF(H3<='Supuestos Generales'!$C$15,'Supuestos Generales'!$D$15,'Supuestos Generales'!$D$16)))) | I6: =IF(I3<='Supuestos Generales'!$C$12,'Supuestos Generales'!$D$12,IF(I3<='Supuestos Generales'!$C$13,'Supuestos Generales'!$D$13,IF(I3<='Supuestos Generales'!$C$14,'Supuestos Generales'!$D$14,IF(I3<='Supuestos Generales'!$C$15,'Supuestos Generales'!$D$15,'Supuestos Generales'!$D$16)))) | ... BI6: =IF(BI3<='Supuestos Generales'!$C$12,'Supuestos Generales'!$D$12,IF(BI3<='Supuestos Generales'!$C$13,'Supuestos Generales'!$D$13,IF(BI3<='Supuestos Generales'!$C$14,'Supuestos Generales'!$D$14,IF(BI3<='Supuestos Generales'!$C$15,'Supuestos Generales'!$D$15,'Supuestos Generales'!$D$16))))
A7: Referidos (mes anterior) | B7: 0 | C7: =(B6+B9)*'Supuestos Generales'!$B$91/2 | D7: =(C6+C9)*'Supuestos Generales'!$B$91/2 | E7: =(D6+D9)*'Supuestos Generales'!$B$91/2 | F7: =(E6+E9)*'Supuestos Generales'!$B$91/2 | G7: =(F6+F9)*'Supuestos Generales'!$B$91/2 | H7: =(G6+G9)*'Supuestos Generales'!$B$91/2 | I7: =(H6+H9)*'Supuestos Generales'!$B$91/2 | J7: =(I6+I9)*'Supuestos Generales'!$B$91/2 | ... BI7: =(BH6+BH9)*'Supuestos Generales'!$B$91/2
A8: Referidos (2 meses antes) | B8: 0 | C8: 0 | D8: =(B6+B9)*'Supuestos Generales'!$B$91/2 | E8: =(C6+C9)*'Supuestos Generales'!$B$91/2 | F8: =(D6+D9)*'Supuestos Generales'!$B$91/2 | G8: =(E6+E9)*'Supuestos Generales'!$B$91/2 | H8: =(F6+F9)*'Supuestos Generales'!$B$91/2 | I8: =(G6+G9)*'Supuestos Generales'!$B$91/2 | J8: =(H6+H9)*'Supuestos Generales'!$B$91/2 | K8: =(I6+I9)*'Supuestos Generales'!$B$91/2 | ... BI8: =(BG6+BG9)*'Supuestos Generales'!$B$91/2
A9: Restaurantes vía alianzas | B9: =IF(AND(Palancas!$B$13=1,B$3>=Palancas!$B$15),MIN(Palancas!$B$16,ROUND(Palancas!$B$16*(B$3-Palancas!$B$15+1)/Palancas!$B$10,0)),0)+IF(AND(Palancas!$F$13=1,B$3>=Palancas!$F$15),MIN(Palancas!$F$16,ROUND(Palancas!$F$16*(B$3-Palancas!$F$15+1)/Palancas!$B$10,0)),0)+IF(AND(Palancas!$B$21=1,B$3>=Palancas!$B$23),MIN(Palancas!$B$24,ROUND(Palancas!$B$24*(B$3-Palancas!$B$23+1)/Palancas!$B$10,0)),0)+IF(AND(Palancas!$F$21=1,B$3>=Palancas!$F$23),MIN(Palancas!$F$24,ROUND(Palancas!$F$24*(B$3-Palancas!$F$23+1)/Palancas!$B$10,0)),0)+IF(AND(Palancas!$B$29=1,B$3>=Palancas!$B$31,B$3<=Palancas!$B$34),MIN(Palancas!$B$32,ROUND(Palancas!$B$32*(B$3-Palancas!$B$31+1)/Palancas!$B$10,0)),0) | C9: =IF(AND(Palancas!$B$13=1,C$3>=Palancas!$B$15),MIN(Palancas!$B$16,ROUND(Palancas!$B$16*(C$3-Palancas!$B$15+1)/Palancas!$B$10,0)),0)+IF(AND(Palancas!$F$13=1,C$3>=Palancas!$F$15),MIN(Palancas!$F$16,ROUND(Palancas!$F$16*(C$3-Palancas!$F$15+1)/Palancas!$B$10,0)),0)+IF(AND(Palancas!$B$21=1,C$3>=Palancas!$B$23),MIN(Palancas!$B$24,ROUND(Palancas!$B$24*(C$3-Palancas!$B$23+1)/Palancas!$B$10,0)),0)+IF(AND(Palancas!$F$21=1,C$3>=Palancas!$F$23),MIN(Palancas!$F$24,ROUND(Palancas!$F$24*(C$3-Palancas!$F$23+1)/Palancas!$B$10,0)),0)+IF(AND(Palancas!$B$29=1,C$3>=Palancas!$B$31,C$3<=Palancas!$B$34),MIN(Palancas!$B$32,ROUND(Palancas!$B$32*(C$3-Palancas!$B$31+1)/Palancas!$B$10,0)),0) | D9: =IF(AND(Palancas!$B$13=1,D$3>=Palancas!$B$15),MIN(Palancas!$B$16,ROUND(Palancas!$B$16*(D$3-Palancas!$B$15+1)/Palancas!$B$10,0)),0)+IF(AND(Palancas!$F$13=1,D$3>=Palancas!$F$15),MIN(Palancas!$F$16,ROUND(Palancas!$F$16*(D$3-Palancas!$F$15+1)/Palancas!$B$10,0)),0)+IF(AND(Palancas!$B$21=1,D$3>=Palancas!$B$23),MIN(Palancas!$B$24,ROUND(Palancas!$B$24*(D$3-Palancas!$B$23+1)/Palancas!$B$10,0)),0)+IF(AND(Palancas!$F$21=1,D$3>=Palancas!$F$23),MIN(Palancas!$F$24,ROUND(Palancas!$F$24*(D$3-Palancas!$F$23+1)/Palancas!$B$10,0)),0)+IF(AND(Palancas!$B$29=1,D$3>=Palancas!$B$31,D$3<=Palancas!$B$34),MIN(Palancas!$B$32,ROUND(Palancas!$B$32*(D$3-Palancas!$B$31+1)/Palancas!$B$10,0)),0) | E9: =IF(AND(Palancas!$B$13=1,E$3>=Palancas!$B$15),MIN(Palancas!$B$16,ROUND(Palancas!$B$16*(E$3-Palancas!$B$15+1)/Palancas!$B$10,0)),0)+IF(AND(Palancas!$F$13=1,E$3>=Palancas!$F$15),MIN(Palancas!$F$16,ROUND(Palancas!$F$16*(E$3-Palancas!$F$15+1)/Palancas!$B$10,0)),0)+IF(AND(Palancas!$B$21=1,E$3>=Palancas!$B$23),MIN(Palancas!$B$24,ROUND(Palancas!$B$24*(E$3-Palancas!$B$23+1)/Palancas!$B$10,0)),0)+IF(AND(Palancas!$F$21=1,E$3>=Palancas!$F$23),MIN(Palancas!$F$24,ROUND(Palancas!$F$24*(E$3-Palancas!$F$23+1)/Palancas!$B$10,0)),0)+IF(AND(Palancas!$B$29=1,E$3>=Palancas!$B$31,E$3<=Palancas!$B$34),MIN(Palancas!$B$32,ROUND(Palancas!$B$32*(E$3-Palancas!$B$31+1)/Palancas!$B$10,0)),0) | F9: =IF(AND(Palancas!$B$13=1,F$3>=Palancas!$B$15),MIN(Palancas!$B$16,ROUND(Palancas!$B$16*(F$3-Palancas!$B$15+1)/Palancas!$B$10,0)),0)+IF(AND(Palancas!$F$13=1,F$3>=Palancas!$F$15),MIN(Palancas!$F$16,ROUND(Palancas!$F$16*(F$3-Palancas!$F$15+1)/Palancas!$B$10,0)),0)+IF(AND(Palancas!$B$21=1,F$3>=Palancas!$B$23),MIN(Palancas!$B$24,ROUND(Palancas!$B$24*(F$3-Palancas!$B$23+1)/Palancas!$B$10,0)),0)+IF(AND(Palancas!$F$21=1,F$3>=Palancas!$F$23),MIN(Palancas!$F$24,ROUND(Palancas!$F$24*(F$3-Palancas!$F$23+1)/Palancas!$B$10,0)),0)+IF(AND(Palancas!$B$29=1,F$3>=Palancas!$B$31,F$3<=Palancas!$B$34),MIN(Palancas!$B$32,ROUND(Palancas!$B$32*(F$3-Palancas!$B$31+1)/Palancas!$B$10,0)),0) | G9: =IF(AND(Palancas!$B$13=1,G$3>=Palancas!$B$15),MIN(Palancas!$B$16,ROUND(Palancas!$B$16*(G$3-Palancas!$B$15+1)/Palancas!$B$10,0)),0)+IF(AND(Palancas!$F$13=1,G$3>=Palancas!$F$15),MIN(Palancas!$F$16,ROUND(Palancas!$F$16*(G$3-Palancas!$F$15+1)/Palancas!$B$10,0)),0)+IF(AND(Palancas!$B$21=1,G$3>=Palancas!$B$23),MIN(Palancas!$B$24,ROUND(Palancas!$B$24*(G$3-Palancas!$B$23+1)/Palancas!$B$10,0)),0)+IF(AND(Palancas!$F$21=1,G$3>=Palancas!$F$23),MIN(Palancas!$F$24,ROUND(Palancas!$F$24*(G$3-Palancas!$F$23+1)/Palancas!$B$10,0)),0)+IF(AND(Palancas!$B$29=1,G$3>=Palancas!$B$31,G$3<=Palancas!$B$34),MIN(Palancas!$B$32,ROUND(Palancas!$B$32*(G$3-Palancas!$B$31+1)/Palancas!$B$10,0)),0) | H9: =IF(AND(Palancas!$B$13=1,H$3>=Palancas!$B$15),MIN(Palancas!$B$16,ROUND(Palancas!$B$16*(H$3-Palancas!$B$15+1)/Palancas!$B$10,0)),0)+IF(AND(Palancas!$F$13=1,H$3>=Palancas!$F$15),MIN(Palancas!$F$16,ROUND(Palancas!$F$16*(H$3-Palancas!$F$15+1)/Palancas!$B$10,0)),0)+IF(AND(Palancas!$B$21=1,H$3>=Palancas!$B$23),MIN(Palancas!$B$24,ROUND(Palancas!$B$24*(H$3-Palancas!$B$23+1)/Palancas!$B$10,0)),0)+IF(AND(Palancas!$F$21=1,H$3>=Palancas!$F$23),MIN(Palancas!$F$24,ROUND(Palancas!$F$24*(H$3-Palancas!$F$23+1)/Palancas!$B$10,0)),0)+IF(AND(Palancas!$B$29=1,H$3>=Palancas!$B$31,H$3<=Palancas!$B$34),MIN(Palancas!$B$32,ROUND(Palancas!$B$32*(H$3-Palancas!$B$31+1)/Palancas!$B$10,0)),0) | I9: =IF(AND(Palancas!$B$13=1,I$3>=Palancas!$B$15),MIN(Palancas!$B$16,ROUND(Palancas!$B$16*(I$3-Palancas!$B$15+1)/Palancas!$B$10,0)),0)+IF(AND(Palancas!$F$13=1,I$3>=Palancas!$F$15),MIN(Palancas!$F$16,ROUND(Palancas!$F$16*(I$3-Palancas!$F$15+1)/Palancas!$B$10,0)),0)+IF(AND(Palancas!$B$21=1,I$3>=Palancas!$B$23),MIN(Palancas!$B$24,ROUND(Palancas!$B$24*(I$3-Palancas!$B$23+1)/Palancas!$B$10,0)),0)+IF(AND(Palancas!$F$21=1,I$3>=Palancas!$F$23),MIN(Palancas!$F$24,ROUND(Palancas!$F$24*(I$3-Palancas!$F$23+1)/Palancas!$B$10,0)),0)+IF(AND(Palancas!$B$29=1,I$3>=Palancas!$B$31,I$3<=Palancas!$B$34),MIN(Palancas!$B$32,ROUND(Palancas!$B$32*(I$3-Palancas!$B$31+1)/Palancas!$B$10,0)),0) | ... BI9: =IF(AND(Palancas!$B$13=1,BI$3>=Palancas!$B$15),MIN(Palancas!$B$16,ROUND(Palancas!$B$16*(BI$3-Palancas!$B$15+1)/Palancas!$B$10,0)),0)+IF(AND(Palancas!$F$13=1,BI$3>=Palancas!$F$15),MIN(Palancas!$F$16,ROUND(Palancas!$F$16*(BI$3-Palancas!$F$15+1)/Palancas!$B$10,0)),0)+IF(AND(Palancas!$B$21=1,BI$3>=Palancas!$B$23),MIN(Palancas!$B$24,ROUND(Palancas!$B$24*(BI$3-Palancas!$B$23+1)/Palancas!$B$10,0)),0)+IF(AND(Palancas!$F$21=1,BI$3>=Palancas!$F$23),MIN(Palancas!$F$24,ROUND(Palancas!$F$24*(BI$3-Palancas!$F$23+1)/Palancas!$B$10,0)),0)+IF(AND(Palancas!$B$29=1,BI$3>=Palancas!$B$31,BI$3<=Palancas!$B$34),MIN(Palancas!$B$32,ROUND(Palancas!$B$32*(BI$3-Palancas!$B$31+1)/Palancas!$B$10,0)),0)
A10: Total restaurantes nuevos (mes) | B10: =B6+B7+B8+B9 | C10: =C6+C7+C8+C9 | D10: =D6+D7+D8+D9 | E10: =E6+E7+E8+E9 | F10: =F6+F7+F8+F9 | G10: =G6+G7+G8+G9 | H10: =H6+H7+H8+H9 | I10: =I6+I7+I8+I9 | ... BI10: =BI6+BI7+BI8+BI9
A11: Churn de restaurantes | B11: 0 | C11: =ROUND(B12*'Supuestos Generales'!$B$18,0) | D11: =ROUND(C12*'Supuestos Generales'!$B$18,0) | E11: =ROUND(D12*'Supuestos Generales'!$B$18,0) | F11: =ROUND(E12*'Supuestos Generales'!$B$18,0) | G11: =ROUND(F12*'Supuestos Generales'!$B$18,0) | H11: =ROUND(G12*'Supuestos Generales'!$B$18,0) | I11: =ROUND(H12*'Supuestos Generales'!$B$18,0) | J11: =ROUND(I12*'Supuestos Generales'!$B$18,0) | ... BI11: =ROUND(BH12*'Supuestos Generales'!$B$18,0)
A12: Restaurantes activos acumulados | B12: =B10-B11 | C12: =B12+C10-C11 | D12: =C12+D10-D11 | E12: =D12+E10-E11 | F12: =E12+F10-F11 | G12: =F12+G10-G11 | H12: =G12+H10-H11 | I12: =H12+I10-I11 | J12: =I12+J10-J11 | ... BI12: =BH12+BI10-BI11
A13: — Pequeños (Plan Light) | B13: =ROUND(B12*'Supuestos Generales'!$B$41,0) | C13: =ROUND(C12*'Supuestos Generales'!$B$41,0) | D13: =ROUND(D12*'Supuestos Generales'!$B$41,0) | E13: =ROUND(E12*'Supuestos Generales'!$B$41,0) | F13: =ROUND(F12*'Supuestos Generales'!$B$41,0) | G13: =ROUND(G12*'Supuestos Generales'!$B$41,0) | H13: =ROUND(H12*'Supuestos Generales'!$B$41,0) | I13: =ROUND(I12*'Supuestos Generales'!$B$41,0) | ... BI13: =ROUND(BI12*'Supuestos Generales'!$B$41,0)
A14: — Medianos (Plan Standard) | B14: =ROUND(B12*'Supuestos Generales'!$B$42,0) | C14: =ROUND(C12*'Supuestos Generales'!$B$42,0) | D14: =ROUND(D12*'Supuestos Generales'!$B$42,0) | E14: =ROUND(E12*'Supuestos Generales'!$B$42,0) | F14: =ROUND(F12*'Supuestos Generales'!$B$42,0) | G14: =ROUND(G12*'Supuestos Generales'!$B$42,0) | H14: =ROUND(H12*'Supuestos Generales'!$B$42,0) | I14: =ROUND(I12*'Supuestos Generales'!$B$42,0) | ... BI14: =ROUND(BI12*'Supuestos Generales'!$B$42,0)
A15: — Grandes (Plan Premium) | B15: =ROUND(B12*'Supuestos Generales'!$B$43,0) | C15: =ROUND(C12*'Supuestos Generales'!$B$43,0) | D15: =ROUND(D12*'Supuestos Generales'!$B$43,0) | E15: =ROUND(E12*'Supuestos Generales'!$B$43,0) | F15: =ROUND(F12*'Supuestos Generales'!$B$43,0) | G15: =ROUND(G12*'Supuestos Generales'!$B$43,0) | H15: =ROUND(H12*'Supuestos Generales'!$B$43,0) | I15: =ROUND(I12*'Supuestos Generales'!$B$43,0) | ... BI15: =ROUND(BI12*'Supuestos Generales'!$B$43,0)
A17: MESEROS
A18: Meseros totales (activos acum. × meseros/rest.) | B18: =B12*'Supuestos Generales'!$B$19 | C18: =C12*'Supuestos Generales'!$B$19 | D18: =D12*'Supuestos Generales'!$B$19 | E18: =E12*'Supuestos Generales'!$B$19 | F18: =F12*'Supuestos Generales'!$B$19 | G18: =G12*'Supuestos Generales'!$B$19 | H18: =H12*'Supuestos Generales'!$B$19 | I18: =I12*'Supuestos Generales'!$B$19 | ... BI18: =BI12*'Supuestos Generales'!$B$19
A19: Meseros activos (× % activación) | B19: =B18*'Supuestos Generales'!$B$20 | C19: =C18*'Supuestos Generales'!$B$20 | D19: =D18*'Supuestos Generales'!$B$20 | E19: =E18*'Supuestos Generales'!$B$20 | F19: =F18*'Supuestos Generales'!$B$20 | G19: =G18*'Supuestos Generales'!$B$20 | H19: =H18*'Supuestos Generales'!$B$20 | I19: =I18*'Supuestos Generales'!$B$20 | ... BI19: =BI18*'Supuestos Generales'!$B$20
A21: MARCAS
A22: Marcas promedio por restaurante | B22: ='Supuestos Generales'!$B$28 | C22: =B22*(1+'Supuestos Generales'!$B$29) | D22: =C22*(1+'Supuestos Generales'!$B$29) | E22: =D22*(1+'Supuestos Generales'!$B$29) | F22: =E22*(1+'Supuestos Generales'!$B$29) | G22: =F22*(1+'Supuestos Generales'!$B$29) | H22: =G22*(1+'Supuestos Generales'!$B$29) | I22: =H22*(1+'Supuestos Generales'!$B$29) | J22: =I22*(1+'Supuestos Generales'!$B$29) | ... BI22: =BH22*(1+'Supuestos Generales'!$B$29)
A23: Total marcas×restaurantes activos | B23: =B22*B12 | C23: =C22*C12 | D23: =D22*D12 | E23: =E22*E12 | F23: =F22*F12 | G23: =G22*G12 | H23: =H22*H12 | I23: =I22*I12 | ... BI23: =BI22*BI12

Sheet Ingresos
A1: INGRESOS — Proyección Mensual
A3: Concepto | B3: 1 | C3: 2 | D3: 3 | E3: 4 | F3: 5 | G3: 6 | H3: 7 | I3: 8 | J3: 9 | K3: 10 | L3: 11 | M3: 12 | N3: 13 | O3: 14 | P3: 15 | Q3: 16 | R3: 17 | S3: 18 | T3: 19 | U3: 20 | V3: 21 | W3: 22 | X3: 23 | Y3: 24 | Z3: 25 | AA3: 26 | AB3: 27 | AC3: 28 | AD3: 29 | AE3: 30 | AF3: 31 | AG3: 32 | AH3: 33 | AI3: 34 | AJ3: 35 | AK3: 36 | AL3: 37 | AM3: 38 | AN3: 39 | AO3: 40 | AP3: 41 | AQ3: 42 | AR3: 43 | AS3: 44 | AT3: 45 | AU3: 46 | AV3: 47 | AW3: 48 | AX3: 49 | AY3: 50 | AZ3: 51 | BA3: 52 | BB3: 53 | BC3: 54 | BD3: 55 | BE3: 56 | BF3: 57 | BG3: 58 | BH3: 59 | BI3: 60 | BJ3: TOTAL
A5: INGRESOS ONE-OFF
A6: SetUp Fee (restaurantes nuevos) | B6: =Onboarding!B10*'Supuestos Generales'!$B$24 | C6: =Onboarding!C10*'Supuestos Generales'!$B$24 | D6: =Onboarding!D10*'Supuestos Generales'!$B$24 | E6: =Onboarding!E10*'Supuestos Generales'!$B$24 | F6: =Onboarding!F10*'Supuestos Generales'!$B$24 | G6: =Onboarding!G10*'Supuestos Generales'!$B$24 | H6: =Onboarding!H10*'Supuestos Generales'!$B$24 | I6: =Onboarding!I10*'Supuestos Generales'!$B$24 | ... BI6: =Onboarding!BI10*'Supuestos Generales'!$B$24 | BJ6: =SUM(B6:BI6)
A7: Entry Fee (nuevas marcas × restaurantes) | B7: =Onboarding!B10*MAX(Onboarding!B22-1,0)*'Supuestos Generales'!$B$25 | C7: =Onboarding!C10*MAX(Onboarding!C22-1,0)*'Supuestos Generales'!$B$25 | D7: =Onboarding!D10*MAX(Onboarding!D22-1,0)*'Supuestos Generales'!$B$25 | E7: =Onboarding!E10*MAX(Onboarding!E22-1,0)*'Supuestos Generales'!$B$25 | F7: =Onboarding!F10*MAX(Onboarding!F22-1,0)*'Supuestos Generales'!$B$25 | G7: =Onboarding!G10*MAX(Onboarding!G22-1,0)*'Supuestos Generales'!$B$25 | H7: =Onboarding!H10*MAX(Onboarding!H22-1,0)*'Supuestos Generales'!$B$25 | I7: =Onboarding!I10*MAX(Onboarding!I22-1,0)*'Supuestos Generales'!$B$25 | ... BI7: =Onboarding!BI10*MAX(Onboarding!BI22-1,0)*'Supuestos Generales'!$B$25 | BJ7: =SUM(B7:BI7)
A8: Total Ingresos One-Off | B8: =B6+B7 | C8: =C6+C7 | D8: =D6+D7 | E8: =E6+E7 | F8: =F6+F7 | G8: =G6+G7 | H8: =H6+H7 | I8: =I6+I7 | ... BI8: =BI6+BI7 | BJ8: =SUM(B8:BI8)
A10: INGRESOS RECURRENTES
A11: SaaS Fee Restaurante (por mesero) | B11: =Onboarding!B19*'Supuestos Generales'!$B$26 | C11: =Onboarding!C19*'Supuestos Generales'!$B$26 | D11: =Onboarding!D19*'Supuestos Generales'!$B$26 | E11: =Onboarding!E19*'Supuestos Generales'!$B$26 | F11: =Onboarding!F19*'Supuestos Generales'!$B$26 | G11: =Onboarding!G19*'Supuestos Generales'!$B$26 | H11: =Onboarding!H19*'Supuestos Generales'!$B$26 | I11: =Onboarding!I19*'Supuestos Generales'!$B$26 | ... BI11: =Onboarding!BI19*'Supuestos Generales'!$B$26 | BJ11: =SUM(B11:BI11)
A12: SaaS Fee Marcas (por mesero × marcas) | B12: =Onboarding!B19*Onboarding!B22*'Supuestos Generales'!$B$27 | C12: =Onboarding!C19*Onboarding!C22*'Supuestos Generales'!$B$27 | D12: =Onboarding!D19*Onboarding!D22*'Supuestos Generales'!$B$27 | E12: =Onboarding!E19*Onboarding!E22*'Supuestos Generales'!$B$27 | F12: =Onboarding!F19*Onboarding!F22*'Supuestos Generales'!$B$27 | G12: =Onboarding!G19*Onboarding!G22*'Supuestos Generales'!$B$27 | H12: =Onboarding!H19*Onboarding!H22*'Supuestos Generales'!$B$27 | I12: =Onboarding!I19*Onboarding!I22*'Supuestos Generales'!$B$27 | ... BI12: =Onboarding!BI19*Onboarding!BI22*'Supuestos Generales'!$B$27 | BJ12: =SUM(B12:BI12)
A13: Fee Upgrade de Plan | B13: =Onboarding!B12*'Supuestos Generales'!$B$59*'Supuestos Generales'!$B$60 | C13: =Onboarding!C12*'Supuestos Generales'!$B$59*'Supuestos Generales'!$B$60 | D13: =Onboarding!D12*'Supuestos Generales'!$B$59*'Supuestos Generales'!$B$60 | E13: =Onboarding!E12*'Supuestos Generales'!$B$59*'Supuestos Generales'!$B$60 | F13: =Onboarding!F12*'Supuestos Generales'!$B$59*'Supuestos Generales'!$B$60 | G13: =Onboarding!G12*'Supuestos Generales'!$B$59*'Supuestos Generales'!$B$60 | H13: =Onboarding!H12*'Supuestos Generales'!$B$59*'Supuestos Generales'!$B$60 | I13: =Onboarding!I12*'Supuestos Generales'!$B$59*'Supuestos Generales'!$B$60 | ... BI13: =Onboarding!BI12*'Supuestos Generales'!$B$59*'Supuestos Generales'!$B$60 | BJ13: =SUM(B13:BI13)
A14: Super Monedas — Restaurantes (bruto) | B14: =Onboarding!B19*'Supuestos Generales'!$B$31 | C14: =Onboarding!C19*'Supuestos Generales'!$B$31 | D14: =Onboarding!D19*'Supuestos Generales'!$B$31 | E14: =Onboarding!E19*'Supuestos Generales'!$B$31 | F14: =Onboarding!F19*'Supuestos Generales'!$B$31 | G14: =Onboarding!G19*'Supuestos Generales'!$B$31 | H14: =Onboarding!H19*'Supuestos Generales'!$B$31 | I14: =Onboarding!I19*'Supuestos Generales'!$B$31 | ... BI14: =Onboarding!BI19*'Supuestos Generales'!$B$31 | BJ14: =SUM(B14:BI14)
A15: Super Monedas — Marcas (bruto) | B15: =Onboarding!B19*Onboarding!B22*'Supuestos Generales'!$B$32 | C15: =Onboarding!C19*Onboarding!C22*'Supuestos Generales'!$B$32 | D15: =Onboarding!D19*Onboarding!D22*'Supuestos Generales'!$B$32 | E15: =Onboarding!E19*Onboarding!E22*'Supuestos Generales'!$B$32 | F15: =Onboarding!F19*Onboarding!F22*'Supuestos Generales'!$B$32 | G15: =Onboarding!G19*Onboarding!G22*'Supuestos Generales'!$B$32 | H15: =Onboarding!H19*Onboarding!H22*'Supuestos Generales'!$B$32 | I15: =Onboarding!I19*Onboarding!I22*'Supuestos Generales'!$B$32 | ... BI15: =Onboarding!BI19*Onboarding!BI22*'Supuestos Generales'!$B$32 | BJ15: =SUM(B15:BI15)
A16: Total Super Monedas (bruto) | B16: =B14+B15 | C16: =C14+C15 | D16: =D14+D15 | E16: =E14+E15 | F16: =F14+F15 | G16: =G14+G15 | H16: =H14+H15 | I16: =I14+I15 | ... BI16: =BI14+BI15 | BJ16: =SUM(B16:BI16)
A17: Total Ingresos Recurrentes | B17: =B11+B12+B13+B16 | C17: =C11+C12+C13+C16 | D17: =D11+D12+D13+D16 | E17: =E11+E12+E13+E16 | F17: =F11+F12+F13+F16 | G17: =G11+G12+G13+G16 | H17: =H11+H12+H13+H16 | I17: =I11+I12+I13+I16 | ... BJ17: =BJ11+BJ12+BJ13+BJ16
A19: TOTAL INGRESOS | B19: =B8+B17 | C19: =C8+C17 | D19: =D8+D17 | E19: =E8+E17 | F19: =F8+F17 | G19: =G8+G17 | H19: =H8+H17 | I19: =I8+I17 | ... BI19: =BI8+BI17 | BJ19: =SUM(B19:BI19)
A20: Ingresos Acumulados | B20: =B19 | C20: =B20+C19 | D20: =C20+D19 | E20: =D20+E19 | F20: =E20+F19 | G20: =F20+G19 | H20: =G20+H19 | I20: =H20+I19 | J20: =I20+J19 | ... BI20: =BH20+BI19 | BJ20: =BJ19

Sheet Costos Directos
A1: COSTOS DIRECTOS — Proyección Mensual
A3: Concepto | B3: 1 | C3: 2 | D3: 3 | E3: 4 | F3: 5 | G3: 6 | H3: 7 | I3: 8 | J3: 9 | K3: 10 | L3: 11 | M3: 12 | N3: 13 | O3: 14 | P3: 15 | Q3: 16 | R3: 17 | S3: 18 | T3: 19 | U3: 20 | V3: 21 | W3: 22 | X3: 23 | Y3: 24 | Z3: 25 | AA3: 26 | AB3: 27 | AC3: 28 | AD3: 29 | AE3: 30 | AF3: 31 | AG3: 32 | AH3: 33 | AI3: 34 | AJ3: 35 | AK3: 36 | AL3: 37 | AM3: 38 | AN3: 39 | AO3: 40 | AP3: 41 | AQ3: 42 | AR3: 43 | AS3: 44 | AT3: 45 | AU3: 46 | AV3: 47 | AW3: 48 | AX3: 49 | AY3: 50 | AZ3: 51 | BA3: 52 | BB3: 53 | BC3: 54 | BD3: 55 | BE3: 56 | BF3: 57 | BG3: 58 | BH3: 59 | BI3: 60 | BJ3: TOTAL
A5: COSTOS VARIABLES
A6: Incentivos / premios por mesero activo | B6: =Onboarding!B19*'Supuestos Generales'!$B$69 | C6: =Onboarding!C19*'Supuestos Generales'!$B$69 | D6: =Onboarding!D19*'Supuestos Generales'!$B$69 | E6: =Onboarding!E19*'Supuestos Generales'!$B$69 | F6: =Onboarding!F19*'Supuestos Generales'!$B$69 | G6: =Onboarding!G19*'Supuestos Generales'!$B$69 | H6: =Onboarding!H19*'Supuestos Generales'!$B$69 | I6: =Onboarding!I19*'Supuestos Generales'!$B$69 | ... BI6: =Onboarding!BI19*'Supuestos Generales'!$B$69 | BJ6: =SUM(B6:BI6)
A7: Costo redención Super Monedas | B7: =(Ingresos!B14+Ingresos!B15)*'Supuestos Generales'!$B$33*'Supuestos Generales'!$B$70 | C7: =(Ingresos!C14+Ingresos!C15)*'Supuestos Generales'!$B$33*'Supuestos Generales'!$B$70 | D7: =(Ingresos!D14+Ingresos!D15)*'Supuestos Generales'!$B$33*'Supuestos Generales'!$B$70 | E7: =(Ingresos!E14+Ingresos!E15)*'Supuestos Generales'!$B$33*'Supuestos Generales'!$B$70 | F7: =(Ingresos!F14+Ingresos!F15)*'Supuestos Generales'!$B$33*'Supuestos Generales'!$B$70 | G7: =(Ingresos!G14+Ingresos!G15)*'Supuestos Generales'!$B$33*'Supuestos Generales'!$B$70 | H7: =(Ingresos!H14+Ingresos!H15)*'Supuestos Generales'!$B$33*'Supuestos Generales'!$B$70 | I7: =(Ingresos!I14+Ingresos!I15)*'Supuestos Generales'!$B$33*'Supuestos Generales'!$B$70 | ... BI7: =(Ingresos!BI14+Ingresos!BI15)*'Supuestos Generales'!$B$33*'Supuestos Generales'!$B$70 | BJ7: =SUM(B7:BI7)
A8: Infraestructura por mesero activo (hosting) | B8: =Onboarding!B19*'Supuestos Generales'!$B$71 | C8: =Onboarding!C19*'Supuestos Generales'!$B$71 | D8: =Onboarding!D19*'Supuestos Generales'!$B$71 | E8: =Onboarding!E19*'Supuestos Generales'!$B$71 | F8: =Onboarding!F19*'Supuestos Generales'!$B$71 | G8: =Onboarding!G19*'Supuestos Generales'!$B$71 | H8: =Onboarding!H19*'Supuestos Generales'!$B$71 | I8: =Onboarding!I19*'Supuestos Generales'!$B$71 | ... BI8: =Onboarding!BI19*'Supuestos Generales'!$B$71 | BJ8: =SUM(B8:BI8)
A9: Soporte por restaurante activo | B9: =Onboarding!B12*'Supuestos Generales'!$B$72 | C9: =Onboarding!C12*'Supuestos Generales'!$B$72 | D9: =Onboarding!D12*'Supuestos Generales'!$B$72 | E9: =Onboarding!E12*'Supuestos Generales'!$B$72 | F9: =Onboarding!F12*'Supuestos Generales'!$B$72 | G9: =Onboarding!G12*'Supuestos Generales'!$B$72 | H9: =Onboarding!H12*'Supuestos Generales'!$B$72 | I9: =Onboarding!I12*'Supuestos Generales'!$B$72 | ... BI9: =Onboarding!BI12*'Supuestos Generales'!$B$72 | BJ9: =SUM(B9:BI9)
A11: COSTOS DE ENGAGEMENT Y PROMOCIÓN
A12: Comunicaciones digitales por mesero activo | B12: =Onboarding!B19*'Supuestos Generales'!$B$77 | C12: =Onboarding!C19*'Supuestos Generales'!$B$77 | D12: =Onboarding!D19*'Supuestos Generales'!$B$77 | E12: =Onboarding!E19*'Supuestos Generales'!$B$77 | F12: =Onboarding!F19*'Supuestos Generales'!$B$77 | G12: =Onboarding!G19*'Supuestos Generales'!$B$77 | H12: =Onboarding!H19*'Supuestos Generales'!$B$77 | I12: =Onboarding!I19*'Supuestos Generales'!$B$77 | ... BI12: =Onboarding!BI19*'Supuestos Generales'!$B$77 | BJ12: =SUM(B12:BI12)
A13: Engagement Managers (cantidad) | B13: =CEILING(Onboarding!B12/'Supuestos Generales'!$B$82,1) | C13: =CEILING(Onboarding!C12/'Supuestos Generales'!$B$82,1) | D13: =CEILING(Onboarding!D12/'Supuestos Generales'!$B$82,1) | E13: =CEILING(Onboarding!E12/'Supuestos Generales'!$B$82,1) | F13: =CEILING(Onboarding!F12/'Supuestos Generales'!$B$82,1) | G13: =CEILING(Onboarding!G12/'Supuestos Generales'!$B$82,1) | H13: =CEILING(Onboarding!H12/'Supuestos Generales'!$B$82,1) | I13: =CEILING(Onboarding!I12/'Supuestos Generales'!$B$82,1) | ... BI13: =CEILING(Onboarding!BI12/'Supuestos Generales'!$B$82,1)
A14: Costo Engagement Managers | B14: =B13*'Supuestos Generales'!$B$81 | C14: =C13*'Supuestos Generales'!$B$81 | D14: =D13*'Supuestos Generales'!$B$81 | E14: =E13*'Supuestos Generales'!$B$81 | F14: =F13*'Supuestos Generales'!$B$81 | G14: =G13*'Supuestos Generales'!$B$81 | H14: =H13*'Supuestos Generales'!$B$81 | I14: =I13*'Supuestos Generales'!$B$81 | ... BI14: =BI13*'Supuestos Generales'!$B$81 | BJ14: =SUM(B14:BI14)
A15: Agentes de Customer Success (cantidad) | B15: =CEILING(Onboarding!B12/'Supuestos Generales'!$B$73,1) | C15: =CEILING(Onboarding!C12/'Supuestos Generales'!$B$73,1) | D15: =CEILING(Onboarding!D12/'Supuestos Generales'!$B$73,1) | E15: =CEILING(Onboarding!E12/'Supuestos Generales'!$B$73,1) | F15: =CEILING(Onboarding!F12/'Supuestos Generales'!$B$73,1) | G15: =CEILING(Onboarding!G12/'Supuestos Generales'!$B$73,1) | H15: =CEILING(Onboarding!H12/'Supuestos Generales'!$B$73,1) | I15: =CEILING(Onboarding!I12/'Supuestos Generales'!$B$73,1) | ... BI15: =CEILING(Onboarding!BI12/'Supuestos Generales'!$B$73,1)
A16: Costo Agentes CS | B16: =B15*'Supuestos Generales'!$B$74 | C16: =C15*'Supuestos Generales'!$B$74 | D16: =D15*'Supuestos Generales'!$B$74 | E16: =E15*'Supuestos Generales'!$B$74 | F16: =F15*'Supuestos Generales'!$B$74 | G16: =G15*'Supuestos Generales'!$B$74 | H16: =H15*'Supuestos Generales'!$B$74 | I16: =I15*'Supuestos Generales'!$B$74 | ... BI16: =BI15*'Supuestos Generales'!$B$74 | BJ16: =SUM(B16:BI16)
A17: Gala Anual Super Meseros (mensualizado) | B17: ='Supuestos Generales'!$B$85*(1.1^MAX(0,CEILING(B$3/12,1)-1)) | C17: ='Supuestos Generales'!$B$85*(1.1^MAX(0,CEILING(C$3/12,1)-1)) | D17: ='Supuestos Generales'!$B$85*(1.1^MAX(0,CEILING(D$3/12,1)-1)) | E17: ='Supuestos Generales'!$B$85*(1.1^MAX(0,CEILING(E$3/12,1)-1)) | F17: ='Supuestos Generales'!$B$85*(1.1^MAX(0,CEILING(F$3/12,1)-1)) | G17: ='Supuestos Generales'!$B$85*(1.1^MAX(0,CEILING(G$3/12,1)-1)) | H17: ='Supuestos Generales'!$B$85*(1.1^MAX(0,CEILING(H$3/12,1)-1)) | I17: ='Supuestos Generales'!$B$85*(1.1^MAX(0,CEILING(I$3/12,1)-1)) | ... BI17: ='Supuestos Generales'!$B$85*(1.1^MAX(0,CEILING(BI$3/12,1)-1)) | BJ17: =SUM(B17:BI17)
A18: Plataforma SaaS comunicaciones | B18: ='Supuestos Generales'!$B$86 | C18: ='Supuestos Generales'!$B$86 | D18: ='Supuestos Generales'!$B$86 | E18: ='Supuestos Generales'!$B$86 | F18: ='Supuestos Generales'!$B$86 | G18: ='Supuestos Generales'!$B$86 | H18: ='Supuestos Generales'!$B$86 | I18: ='Supuestos Generales'!$B$86 | ... BI18: ='Supuestos Generales'!$B$86 | BJ18: =SUM(B18:BI18)
A19: Total Costos Engagement | B19: =SUM(B12,B14:B18) | C19: =SUM(C12,C14:C18) | D19: =SUM(D12,D14:D18) | E19: =SUM(E12,E14:E18) | F19: =SUM(F12,F14:F18) | G19: =SUM(G12,G14:G18) | H19: =SUM(H12,H14:H18) | I19: =SUM(I12,I14:I18) | ... BI19: =SUM(BI12,BI14:BI18) | BJ19: =SUM(B19:BI19)
A22: DESCUENTO POR REFERIDOS
